<?xml version="1.0" ?>
<!-- =================================================================================== -->
<!-- |    This document was autogenerated by xacro from /home/ros/melodic/src/project_shokunin/shokunin_ros_pkg/shokunin_ros_pkg/robot_config/robot_description/urdf/panda/panda_arm_robotiq.urdf.xacro | -->
<!-- |    EDITING THIS FILE BY HAND IS NOT RECOMMENDED                                 | -->
<!-- =================================================================================== -->
<robot name="panda">
	<!-- basic, tweezer, tactile_pads -->
	<!-- end for simulation -->
	<link name="world" />
	<joint name="panda_joint_world" type="fixed">
		<parent link="world"/>
		<child link="panda_link0"/>
		<origin rpy="0 0 0" xyz="0 0 0"/>
		<!-- for simulation -->
		<dynamics damping="1.0"/>
		<!-- end for simulation -->
	</joint>
	<link name="panda_link0">
		<visual>
			<geometry>
				<mesh filename="file:///root/MOTION_CONTROL_BENCHMARK/robots/meshes/panda_arm/visual/link0.dae"/>
			</geometry>
		</visual>
		<collision>
			<origin rpy="0 1.5707963267948966 0" xyz="-0.075 0 0.06"/>
			<geometry>
				<cylinder length="0.03" radius="0.09"/>
			</geometry>
		</collision>
		<collision>
			<origin xyz="-0.06 0 0.06"/>
			<geometry>
				<sphere radius="0.09"/>
			</geometry>
		</collision>
		<collision>
			<origin xyz="-0.09 0 0.06"/>
			<geometry>
				<sphere radius="0.09"/>
			</geometry>
		</collision>
		<!-- for simulation -->
		<inertial>
			<origin rpy="0 0 0" xyz="0 0 0"/>
			<mass value="3.06"/>
			<inertia ixx="0.3" ixy="0.0" ixz="0.0" iyy="0.3" iyz="0.0" izz="0.3"/>
		</inertial>
		<!-- end for simulation -->
	</link>
	<link name="panda_link1">
		<visual>
			<geometry>
				<mesh filename="file:///root/MOTION_CONTROL_BENCHMARK/robots/meshes/panda_arm/visual/link1.dae"/>
			</geometry>
		</visual>
		<collision>
			<origin rpy="0 0 0" xyz="0 0 -0.1915"/>
			<geometry>
				<cylinder length="0.283" radius="0.09"/>
			</geometry>
		</collision>
		<collision>
			<origin xyz="0 0 -0.05000000000000002"/>
			<geometry>
				<sphere radius="0.09"/>
			</geometry>
		</collision>
		<collision>
			<origin xyz="0 0 -0.33299999999999996"/>
			<geometry>
				<sphere radius="0.09"/>
			</geometry>
		</collision>
		<!-- for simulation -->
		<inertial>
			<origin rpy="0 0 0" xyz="0 0 0"/>
			<mass value="2.34"/>
			<inertia ixx="0.3" ixy="0.0" ixz="0.0" iyy="0.3" iyz="0.0" izz="0.3"/>
		</inertial>
		<!-- end for simulation -->
	</link>
	<joint name="panda_joint1" type="revolute">
		<safety_controller k_position="100.0" k_velocity="40.0" soft_lower_limit="-2.8973" soft_upper_limit="2.8973"/>
		<origin rpy="0 0 0" xyz="0 0 0.333"/>
		<parent link="panda_link0"/>
		<child link="panda_link1"/>
		<axis xyz="0 0 1"/>
		<dynamics damping="1.0"/>
		<limit effort="87" lower="-2.8973" upper="2.8973" velocity="2.1750"/>
	</joint>
	<link name="panda_link2">
		<visual>
			<geometry>
				<mesh filename="file:///root/MOTION_CONTROL_BENCHMARK/robots/meshes/panda_arm/visual/link2.dae"/>
			</geometry>
		</visual>
		<collision>
			<origin rpy="0 0 0" xyz="0 0 0"/>
			<geometry>
				<cylinder length="0.12" radius="0.09"/>
			</geometry>
		</collision>
		<collision>
			<origin rpy="0 0 0" xyz="0 0 -0.06"/>
			<geometry>
				<sphere radius="0.09"/>
			</geometry>
		</collision>
		<collision>
			<origin rpy="0 0 0" xyz="0 0 0.06"/>
			<geometry>
				<sphere radius="0.09"/>
			</geometry>
		</collision>
		<!-- for simulation -->
		<inertial>
			<origin rpy="0 0 0" xyz="0 0 0"/>
			<mass value="2.36"/>
			<inertia ixx="0.3" ixy="0.0" ixz="0.0" iyy="0.3" iyz="0.0" izz="0.3"/>
		</inertial>
		<!-- end for simulation -->
	</link>
	<joint name="panda_joint2" type="revolute">
		<safety_controller k_position="100.0" k_velocity="40.0" soft_lower_limit="-1.7628" soft_upper_limit="1.7628"/>
		<origin rpy="-1.5707963267948966 0 0" xyz="0 0 0"/>
		<parent link="panda_link1"/>
		<child link="panda_link2"/>
		<axis xyz="0 0 1"/>
		<dynamics damping="1.0"/>
		<limit effort="87" lower="-1.7628" upper="1.7628" velocity="2.1750"/>
	</joint>
	<link name="panda_link3">
		<visual>
			<geometry>
				<mesh filename="file:///root/MOTION_CONTROL_BENCHMARK/robots/meshes/panda_arm/visual/link3.dae"/>
			</geometry>
		</visual>
		<collision>
			<origin rpy="0 0 0" xyz="0 0 -0.145"/>
			<geometry>
				<cylinder length="0.15" radius="0.09"/>
			</geometry>
		</collision>
		<collision>
			<origin rpy="0 0 0" xyz="0 0 -0.22"/>
			<geometry>
				<sphere radius="0.09"/>
			</geometry>
		</collision>
		<collision>
			<origin rpy="0 0 0" xyz="0 0 -0.07"/>
			<geometry>
				<sphere radius="0.09"/>
			</geometry>
		</collision>
		<!-- for simulation -->
		<inertial>
			<origin rpy="0 0 0" xyz="0 0 0"/>
			<mass value="2.38"/>
			<inertia ixx="0.3" ixy="0.0" ixz="0.0" iyy="0.3" iyz="0.0" izz="0.3"/>
		</inertial>
		<!-- end for simulation -->
	</link>
	<joint name="panda_joint3" type="revolute">
		<safety_controller k_position="100.0" k_velocity="40.0" soft_lower_limit="-2.8973" soft_upper_limit="2.8973"/>
		<origin rpy="1.5707963267948966 0 0" xyz="0 -0.316 0"/>
		<parent link="panda_link2"/>
		<child link="panda_link3"/>
		<axis xyz="0 0 1"/>
		<dynamics damping="1.0"/>
		<limit effort="87" lower="-2.8973" upper="2.8973" velocity="2.1750"/>
	</joint>
	<link name="panda_link4">
		<visual>
			<geometry>
				<mesh filename="file:///root/MOTION_CONTROL_BENCHMARK/robots/meshes/panda_arm/visual/link4.dae"/>
			</geometry>
		</visual>
		<collision>
			<origin rpy="0 0 0" xyz="0 0 0"/>
			<geometry>
				<cylinder length="0.12" radius="0.09"/>
			</geometry>
		</collision>
		<collision>
			<origin rpy="0 0 0" xyz="0 0 0.06"/>
			<geometry>
				<sphere radius="0.09"/>
			</geometry>
		</collision>
		<collision>
			<origin rpy="0 0 0" xyz="0 0 -0.06"/>
			<geometry>
				<sphere radius="0.09"/>
			</geometry>
		</collision>
		<!-- for simulation -->
		<inertial>
			<origin rpy="0 0 0" xyz="0 0 0"/>
			<mass value="2.43"/>
			<inertia ixx="0.3" ixy="0.0" ixz="0.0" iyy="0.3" iyz="0.0" izz="0.3"/>
		</inertial>
		<!-- end for simulation -->
	</link>
	<joint name="panda_joint4" type="revolute">
		<safety_controller k_position="100.0" k_velocity="40.0" soft_lower_limit="-3.0718" soft_upper_limit="-0.0698"/>
		<origin rpy="1.5707963267948966 0 0" xyz="0.0825 0 0"/>
		<parent link="panda_link3"/>
		<child link="panda_link4"/>
		<axis xyz="0 0 1"/>
		<dynamics damping="1.0"/>
		<limit effort="87" lower="-3.0718" upper="-0.0698" velocity="2.1750"/>
	</joint>
	<link name="panda_link5">
		<visual>
			<geometry>
				<mesh filename="file:///root/MOTION_CONTROL_BENCHMARK/robots/meshes/panda_arm/visual/link5.dae"/>
			</geometry>
		</visual>
		<collision>
			<origin rpy="0 0 0" xyz="0 0 -0.26"/>
			<geometry>
				<cylinder length="0.1" radius="0.09"/>
			</geometry>
		</collision>
		<collision>
			<origin rpy="0 0 0" xyz="0 0 -0.31"/>
			<geometry>
				<sphere radius="0.09"/>
			</geometry>
		</collision>
		<collision>
			<origin rpy="0 0 0" xyz="0 0 -0.21"/>
			<geometry>
				<sphere radius="0.09"/>
			</geometry>
		</collision>
		<collision>
			<origin rpy="0 0 0" xyz="0 0.08 -0.13"/>
			<geometry>
				<cylinder length="0.14" radius="0.055"/>
			</geometry>
		</collision>
		<collision>
			<origin rpy="0 0 0" xyz="0 0.08 -0.06"/>
			<geometry>
				<sphere radius="0.055"/>
			</geometry>
		</collision>
		<collision>
			<origin rpy="0 0 0" xyz="0 0.08 -0.20"/>
			<geometry>
				<sphere radius="0.055"/>
			</geometry>
		</collision>
		<!-- for simulation -->
		<inertial>
			<origin rpy="0 0 0" xyz="0 0 0"/>
			<mass value="3.5"/>
			<inertia ixx="0.3" ixy="0.0" ixz="0.0" iyy="0.3" iyz="0.0" izz="0.3"/>
		</inertial>
		<!-- end for simulation -->
	</link>
	<joint name="panda_joint5" type="revolute">
		<safety_controller k_position="100.0" k_velocity="40.0" soft_lower_limit="-2.8973" soft_upper_limit="2.8973"/>
		<origin rpy="-1.5707963267948966 0 0" xyz="-0.0825 0.384 0"/>
		<parent link="panda_link4"/>
		<child link="panda_link5"/>
		<axis xyz="0 0 1"/>
		<dynamics damping="1.0"/>
		<limit effort="12" lower="-2.8973" upper="2.8973" velocity="2.6100"/>
	</joint>
	<link name="panda_link6">
		<visual>
			<geometry>
				<mesh filename="file:///root/MOTION_CONTROL_BENCHMARK/robots/meshes/panda_arm/visual/link6.dae"/>
			</geometry>
		</visual>
		<collision>
			<origin rpy="0 0 0" xyz="0 0 -0.03"/>
			<geometry>
				<cylinder length="0.08" radius="0.08"/>
			</geometry>
		</collision>
		<collision>
			<origin rpy="0 0 0" xyz="0 0 0.01"/>
			<geometry>
				<sphere radius="0.08"/>
			</geometry>
		</collision>
		<collision>
			<origin rpy="0 0 0" xyz="0 0 -0.07"/>
			<geometry>
				<sphere radius="0.08"/>
			</geometry>
		</collision>
		<!-- for simulation -->
		<inertial>
			<origin rpy="0 0 0" xyz="0 0 0"/>
			<mass value="1.47"/>
			<inertia ixx="0.3" ixy="0.0" ixz="0.0" iyy="0.3" iyz="0.0" izz="0.3"/>
		</inertial>
		<!-- end for simulation -->
	</link>
	<joint name="panda_joint6" type="revolute">
		<safety_controller k_position="100.0" k_velocity="40.0" soft_lower_limit="-0.0175" soft_upper_limit="3.7525"/>
		<origin rpy="1.5707963267948966 0 0" xyz="0 0 0"/>
		<parent link="panda_link5"/>
		<child link="panda_link6"/>
		<axis xyz="0 0 1"/>
		<dynamics damping="1.0"/>
		<limit effort="12" lower="-0.0175" upper="3.7525" velocity="2.6100"/>
	</joint>
	<link name="panda_link7">
		<visual>
			<geometry>
				<mesh filename="file:///root/MOTION_CONTROL_BENCHMARK/robots/meshes/panda_arm/visual/link7.dae"/>
			</geometry>
		</visual>
		<collision>
			<origin rpy="0 0 0" xyz="0 0 0.01"/>
			<geometry>
				<cylinder length="0.14" radius="0.07"/>
			</geometry>
		</collision>
		<collision>
			<origin rpy="0 0 0" xyz="0 0 0.08"/>
			<geometry>
				<sphere radius="0.07"/>
			</geometry>
		</collision>
		<collision>
			<origin rpy="0 0 0" xyz="0 0 -0.06"/>
			<geometry>
				<sphere radius="0.07"/>
			</geometry>
		</collision>
		<!-- for simulation -->
		<inertial>
			<origin rpy="0 0 0" xyz="0 0 0"/>
			<mass value="0.45"/>
			<inertia ixx="0.3" ixy="0.0" ixz="0.0" iyy="0.3" iyz="0.0" izz="0.3"/>
		</inertial>
		<!-- end for simulation -->
	</link>
	<joint name="panda_joint7" type="revolute">
		<safety_controller k_position="100.0" k_velocity="40.0" soft_lower_limit="-2.8973" soft_upper_limit="2.8973"/>
		<origin rpy="1.5707963267948966 0 0" xyz="0.088 0 0"/>
		<parent link="panda_link6"/>
		<child link="panda_link7"/>
		<axis xyz="0 0 1"/>
		<dynamics damping="1.0"/>
		<limit effort="12" lower="-2.8973" upper="2.8973" velocity="2.6100"/>
	</joint>
	<link name="panda_link8"/>
	<joint name="panda_joint8" type="fixed">
		<origin rpy="0 0 0" xyz="0 0 0.107"/>
		<parent link="panda_link7"/>
		<child link="panda_link8"/>
	</joint>
	<joint name="robotiq_85_coupling_joint" type="fixed">
		<parent link="panda_link8"/>
		<child link="robotiq_coupling_link"/>
		<origin rpy="0 0 1.57079632679" xyz="0 0 0"/>
	</joint>
	<link name="robotiq_coupling_link">
		<inertial>
			<origin rpy="0 0 0" xyz="8.625E-08 -4.6583E-06 0.03145"/>
			<mass value="0.22652"/>
			<inertia ixx="0.00020005" ixy="-4.2442E-10" ixz="-2.9069E-10" iyy="0.00017832" iyz="-3.4402E-08" izz="0.00013478"/>
		</inertial>
		<visual>
			<origin rpy="0 0 0" xyz="0 0 0"/>
			<geometry>
				<mesh filename="file:///root/MOTION_CONTROL_BENCHMARK/robots/meshes/robotiq_gripper_with_tweezer/robotiq_gripper_coupling.dae" scale="0.001 0.001 0.001"/>
			</geometry>
			<material name="">
				<color rgba="0.2 0.2 0.2 1"/>
			</material>
		</visual>
		<collision>
			<origin rpy="0 0 0" xyz="0 0 0"/>
			<geometry>
				<mesh filename="file:///root/MOTION_CONTROL_BENCHMARK/robots/meshes/robotiq_gripper_with_tweezer/robotiq_gripper_coupling.dae" scale="0.001 0.001 0.001"/>
			</geometry>
		</collision>
	</link>
	<joint name="robotiq_85_base_joint" type="fixed">
		<parent link="robotiq_coupling_link"/>
		<child link="robotiq_85_base_link"/>
		<origin rpy="0 -1.5708 0" xyz="0 0 0.00825"/>
	</joint>
	<link name="robotiq_85_base_link">
		<visual>
			<geometry>
				<mesh filename="file:///root/MOTION_CONTROL_BENCHMARK/robots/meshes/robotiq_gripper_with_tweezer/visual/robotiq_85_base_link.dae"/>
			</geometry>
		</visual>
		<collision>
			<geometry>
				<!-- We use a signle simplified collision shape to cover for "robotiq_85_base_link"
  , "robotiq_85_left_knuckle_link", "robotiq_85_right_knuckle_link", "robotiq_85_left_finger_link"
  , 'robotiq_85_right_finger_link', "robotiq_85_left_inner_knuckle_link", and "
  robotiq_85_right_inner_knuckle_link". These other links don't need a collision\
 shape anymore. -->
				<mesh filename="file:///root/MOTION_CONTROL_BENCHMARK/robots/meshes/robotiq_gripper_with_tweezer/collision/robotiq_85_base_link_simplified.stl"/>
			</geometry>
		</collision>
		<inertial>
			<mass value="0.636951"/>
			<origin xyz="0.0 0.0 0.0"/>
			<inertia ixx="0.000380" ixy="0.000000" ixz="0.000000" iyx="0.000000" iyy="0.001110" iyz="0.000000" izx="0.000000" izy="0.000000" izz="0.001171"/>
		</inertial>
	</link>
	<gazebo reference="robotiq_85_base_link">
		<collision>
			<surface>

				<contact>
					<collide_bitmask>0x01</collide_bitmask>
				</contact>
			</surface>
		</collision>
	</gazebo>
	<joint name="robotiq_85_left_knuckle_joint" type="revolute">
		<parent link="robotiq_85_base_link"/>
		<child link="robotiq_85_left_knuckle_link"/>
		<axis xyz="0 0 1"/>
		<origin rpy="3.14159265359 0.0 0.0" xyz="0.05490451627 0.03060114443 0.0"/>
		<limit effort="1000" lower="0.0" upper="0.804" velocity="2.0"/>
	</joint>
	<joint name="robotiq_85_right_knuckle_joint" type="continuous">
		<parent link="robotiq_85_base_link"/>
		<child link="robotiq_85_right_knuckle_link"/>
		<axis xyz="0 0 1"/>
		<origin rpy="0.0 0.0 0.0" xyz="0.05490451627 -0.03060114443 0.0"/>
		<limit effort="1000" lower="-3.14" upper="3.14" velocity="100.0"/>
		<mimic joint="robotiq_85_left_knuckle_joint"/>
	</joint>
	<link name="robotiq_85_left_knuckle_link">
		<visual>
			<geometry>
				<mesh filename="file:///root/MOTION_CONTROL_BENCHMARK/robots/meshes/robotiq_gripper_with_tweezer/visual/robotiq_85_knuckle_link.dae"/>
			</geometry>
		</visual>
		<inertial>
			<mass value="0.018491"/>
			<origin xyz="0.0 0.0 0.0"/>
			<inertia ixx="0.000009" ixy="-0.000001" ixz="0.000000" iyx="-0.000001" iyy="0.000001" iyz="0.000000" izx="0.000000" izy="0.000000" izz="0.000010"/>
		</inertial>
	</link>
	<link name="robotiq_85_right_knuckle_link">
		<visual>
			<geometry>
				<mesh filename="file:///root/MOTION_CONTROL_BENCHMARK/robots/meshes/robotiq_gripper_with_tweezer/visual/robotiq_85_knuckle_link.dae"/>
			</geometry>
		</visual>
		<inertial>
			<mass value="0.018491"/>
			<origin xyz="0.0 0.0 0.0"/>
			<inertia ixx="0.000009" ixy="-0.000001" ixz="0.000000" iyx="-0.000001" iyy="0.000001" iyz="0.000000" izx="0.000000" izy="0.000000" izz="0.000010"/>
		</inertial>
	</link>
	<joint name="robotiq_85_left_finger_joint" type="fixed">
		<parent link="robotiq_85_left_knuckle_link"/>
		<child link="robotiq_85_left_finger_link"/>
		<origin rpy="0 0 0" xyz="-0.00408552455 -0.03148604435 0.0"/>
	</joint>
	<joint name="robotiq_85_right_finger_joint" type="fixed">
		<parent link="robotiq_85_right_knuckle_link"/>
		<child link="robotiq_85_right_finger_link"/>
		<origin rpy="0 0 0" xyz="-0.00408552455 -0.03148604435 0.0"/>
	</joint>
	<link name="robotiq_85_left_finger_link">
		<visual>
			<geometry>
				<mesh filename="file:///root/MOTION_CONTROL_BENCHMARK/robots/meshes/robotiq_gripper_with_tweezer/visual/robotiq_85_finger_link.dae"/>
			</geometry>
		</visual>
		<inertial>
			<mass value="0.027309"/>
			<origin xyz="0.0 0.0 0.0"/>
			<inertia ixx="0.000003" ixy="-0.000002" ixz="0.000000" iyx="-0.000002" iyy="0.000021" iyz="0.000000" izx="0.000000" izy="0.000000" izz="0.000020"/>
		</inertial>
	</link>
	<link name="robotiq_85_right_finger_link">
		<visual>
			<geometry>
				<mesh filename="file:///root/MOTION_CONTROL_BENCHMARK/robots/meshes/robotiq_gripper_with_tweezer/visual/robotiq_85_finger_link.dae"/>
			</geometry>
		</visual>
		<inertial>
			<mass value="0.027309"/>
			<origin xyz="0.0 0.0 0.0"/>
			<inertia ixx="0.000003" ixy="-0.000002" ixz="0.000000" iyx="-0.000002" iyy="0.000021" iyz="0.000000" izx="0.000000" izy="0.000000" izz="0.000020"/>
		</inertial>
	</link>
	<joint name="robotiq_85_left_inner_knuckle_joint" type="continuous">

		<parent link="robotiq_85_base_link"/>
		<child link="robotiq_85_left_inner_knuckle_link"/>
		<axis xyz="0 0 1"/>
		<origin rpy="3.14159265359 0.0 0.0" xyz="0.06142 0.0127 0"/>
		<limit effort="0.1" lower="-3.14" upper="3.14" velocity="100.0"/>
		<mimic joint="robotiq_85_left_knuckle_joint" offset="0"/>
	</joint>
	<joint name="robotiq_85_right_inner_knuckle_joint" type="continuous">
		<parent link="robotiq_85_base_link"/>
		<child link="robotiq_85_right_inner_knuckle_link"/>
		<axis xyz="0 0 1"/>
		<origin rpy="0 0 0" xyz="0.06142 -0.0127 0"/>
		<limit effort="0.1" lower="-3.14" upper="3.14" velocity="100.0"/>
		<mimic joint="robotiq_85_left_knuckle_joint" offset="0"/>
	</joint>
	<link name="robotiq_85_left_inner_knuckle_link">
		<visual>
			<geometry>
				<mesh filename="file:///root/MOTION_CONTROL_BENCHMARK/robots/meshes/robotiq_gripper_with_tweezer/visual/robotiq_85_inner_knuckle_link.dae"/>
			</geometry>
		</visual>
		<inertial>
			<mass value="0.029951"/>
			<origin xyz="0.0 0.0 0.0"/>
			<inertia ixx="0.000039" ixy="0.000000" ixz="0.000000" iyx="0.000000" iyy="0.000005" iyz="0.000000" izx="0.000000" izy="0.000000" izz="0.000035"/>
		</inertial>
	</link>
	<link name="robotiq_85_right_inner_knuckle_link">
		<visual>
			<geometry>
				<mesh filename="file:///root/MOTION_CONTROL_BENCHMARK/robots/meshes/robotiq_gripper_with_tweezer/visual/robotiq_85_inner_knuckle_link.dae"/>
			</geometry>
		</visual>
		<inertial>
			<mass value="0.029951"/>
			<origin xyz="0.0 0.0 0.0"/>
			<inertia ixx="0.000039" ixy="0.000000" ixz="0.000000" iyx="0.000000" iyy="0.000005" iyz="0.000000" izx="0.000000" izy="0.000000" izz="0.000035"/>
		</inertial>
	</link>
	<joint name="robotiq_85_left_finger_tip_joint" type="continuous">
		<parent link="robotiq_85_left_inner_knuckle_link"/>
		<child link="robotiq_85_left_finger_tip_link"/>
		<axis xyz="0 0 1"/>
		<origin rpy="0.0 0.0 3.14" xyz="0.04303959807 -0.03759940821 0.0"/>
		<limit effort="0.1" lower="-3.14" upper="3.14" velocity="100.0"/>
		<mimic joint="robotiq_85_left_knuckle_joint" multiplier="-1"/>
	</joint>
	<joint name="robotiq_85_right_finger_tip_joint" type="continuous">
		<parent link="robotiq_85_right_inner_knuckle_link"/>
		<child link="robotiq_85_right_finger_tip_link"/>
		<axis xyz="0 0 1"/>
		<origin rpy="0.0 0.0 3.14" xyz="0.04303959807 -0.03759940821  0.0"/>
		<limit effort="0.1" lower="-3.14" upper="3.14" velocity="100.0"/>
		<mimic joint="robotiq_85_left_knuckle_joint" multiplier="-1"/>
	</joint>
	<link name="robotiq_85_left_finger_tip_link">
		<visual>
			<geometry>
				<mesh filename="file:///root/MOTION_CONTROL_BENCHMARK/robots/meshes/robotiq_gripper_with_tweezer/visual/robotiq_85_finger_tip_link_right.dae" scale="0.001 0.001 0.001"/>
			</geometry>
		</visual>
		<collision>
			<geometry>
				<mesh filename="file:///root/MOTION_CONTROL_BENCHMARK/robots/meshes/robotiq_gripper_with_tweezer/collision/robotiq_85_finger_tip_link_right.stl" scale="0.001 0.001 0.001"/>
			</geometry>
		</collision>
		<inertial>
			<mass value="0.019555"/>
			<origin xyz="0.0 0.0 0.0"/>
			<inertia ixx="0.000002" ixy="0.000000" ixz="0.000000" iyx="0.000000" iyy="0.000005" iyz="0.000000" izx="0.000000" izy="0.000000" izz="0.000006"/>
		</inertial>
	</link>
	<gazebo reference="robotiq_85_left_finger_tip_link">
		<collision>
			<surface>
				<contact>
					<collide_bitmask>0x02</collide_bitmask>
				</contact>
			</surface>
		</collision>
	</gazebo>
	<link name="robotiq_85_right_finger_tip_link">
		<visual>
			<geometry>
				<mesh filename="file:///root/MOTION_CONTROL_BENCHMARK/robots/meshes/robotiq_gripper_with_tweezer/visual/robotiq_85_finger_tip_link_left.dae" scale="0.001 0.001 0.001"/>
			</geometry>
		</visual>
		<collision>
			<geometry>
				<mesh filename="file:///root/MOTION_CONTROL_BENCHMARK/robots/meshes/robotiq_gripper_with_tweezer/collision/robotiq_85_finger_tip_link_left.stl" scale="0.001 0.001 0.001"/>
			</geometry>
		</collision>
		<inertial>
			<mass value="0.019555"/>
			<origin xyz="0.0 0.0 0.0"/>
			<inertia ixx="0.000002" ixy="0.000000" ixz="0.000000" iyx="0.000000" iyy="0.000005" iyz="0.000000" izx="0.000000" izy="0.000000" izz="0.000006"/>
		</inertial>
	</link>
	<gazebo reference="robotiq_85_right_finger_tip_link">
		<collision>
			<surface>
				<contact>
					<collide_bitmask>0x02</collide_bitmask>
				</contact>
			</surface>
		</collision>
	</gazebo>
	<transmission name="robotiq_85_left_knuckle_trans">
		<type>transmission_interface/SimpleTransmission</type>
		<joint name="robotiq_85_left_knuckle_joint">
			<hardwareInterface>hardware_interface/PositionJointInterface</hardwareInterface>
		</joint>
		<actuator name="robotiq_85_left_knuckle_motor">
			<mechanicalReduction>1</mechanicalReduction>
			<hardwareInterface>hardware_interface/PositionJointInterface</hardwareInterface>
		</actuator>
	</transmission>
	<gazebo>
		<!-- loading plugin: mimic joints works in gazebo now -->
		<plugin filename="libroboticsgroup_gazebo_mimic_joint_plugin.so" name="mimic_robotiq_85_1">
			<joint>robotiq_85_left_knuckle_joint</joint>
			<mimicJoint>robotiq_85_right_knuckle_joint</mimicJoint>
			<!--multiplier>1.0</multiplier>
				<offset>0.0</offset-->
		</plugin>
		<plugin filename="libroboticsgroup_gazebo_mimic_joint_plugin.so" name="mimic_robotiq_85_2">
			<joint>robotiq_85_left_knuckle_joint</joint>
			<mimicJoint>robotiq_85_left_inner_knuckle_joint</mimicJoint>
			<!--multiplier>1.0</multiplier>
				<offset>0.0</offset-->
		</plugin>
		<plugin filename="libroboticsgroup_gazebo_mimic_joint_plugin.so" name="mimic_robotiq_85_3">
			<joint>robotiq_85_left_knuckle_joint</joint>
			<mimicJoint>robotiq_85_right_inner_knuckle_joint</mimicJoint>
			<!--multiplier>1.0</multiplier>
				<offset>0.0</offset-->
		</plugin>
		<plugin filename="libroboticsgroup_gazebo_mimic_joint_plugin.so" name="mimic_robotiq_85_4">
			<joint>robotiq_85_left_knuckle_joint</joint>
			<mimicJoint>robotiq_85_left_finger_tip_joint</mimicJoint>
			<multiplier>-1.0</multiplier>
			<offset>0.0</offset>
		</plugin>
		<plugin filename="libroboticsgroup_gazebo_mimic_joint_plugin.so" name="mimic_robotiq_85_5">
			<joint>robotiq_85_left_knuckle_joint</joint>
			<mimicJoint>robotiq_85_right_finger_tip_joint</mimicJoint>
			<multiplier>-1.0</multiplier>
			<offset>0.0</offset>
		</plugin>
	</gazebo>
	<gazebo reference="base_link">
		<mu1>0.2</mu1>
		<mu2>0.2</mu2>
	</gazebo>
	<gazebo reference="shoulder_link">
		<mu1>0.2</mu1>
		<mu2>0.2</mu2>
	</gazebo>
	<gazebo reference="upper_arm_link">
		<mu1>0.2</mu1>
		<mu2>0.2</mu2>
	</gazebo>
	<gazebo reference="ee_link">
		<mu1>0.2</mu1>
		<mu2>0.2</mu2>
	</gazebo>
	<gazebo reference="forearm_link">
		<mu1>0.2</mu1>
		<mu2>0.2</mu2>
	</gazebo>
	<gazebo reference="wrist_1_link">
		<mu1>0.2</mu1>
		<mu2>0.2</mu2>
	</gazebo>
	<gazebo reference="wrist_2_link">
		<mu1>0.2</mu1>
		<mu2>0.2</mu2>
	</gazebo>
	<gazebo reference="wrist_3_link">
		<mu1>0.2</mu1>
		<mu2>0.2</mu2>
	</gazebo>
	<gazebo reference="robotiq_85_base_link">
		<provideFeedback>true</provideFeedback>
		<material>Gazebo/Black</material>
		<implicitSpringDamper>1</implicitSpringDamper>
		<mu1>10</mu1>
		<mu2>100</mu2>
		<minDepth>0.005</minDepth>
		<maxVel>0</maxVel>
		<kp>1e+13</kp>
		<kd>1.0</kd>
		<maxContacts>10</maxContacts>
	</gazebo>
	<gazebo reference="robotiq_85_left_inner_knuckle_link">
		<provideFeedback>true</provideFeedback>
		<material>Gazebo/Black</material>
		<implicitSpringDamper>1</implicitSpringDamper>
		<mu1>10</mu1>
		<mu2>100</mu2>
		<minDepth>0.005</minDepth>
		<maxVel>0</maxVel>
		<kp>1e+13</kp>
		<kd>1.0</kd>
		<maxContacts>10</maxContacts>
	</gazebo>
	<gazebo reference="robotiq_85_left_finger_tip_link">
		<provideFeedback>true</provideFeedback>
		<material>Gazebo/Black</material>
		<implicitSpringDamper>1</implicitSpringDamper>
		<mu1>10</mu1>
		<mu2>100</mu2>
		<minDepth>0.005</minDepth>
		<maxVel>0</maxVel>
		<kp>1e+13</kp>
		<kd>1.0</kd>
		<maxContacts>10</maxContacts>
	</gazebo>
	<gazebo reference="robotiq_85_left_knuckle_link">
		<provideFeedback>true</provideFeedback>
		<material>Gazebo/Black</material>
		<implicitSpringDamper>1</implicitSpringDamper>
		<mu1>10</mu1>
		<mu2>100</mu2>
		<minDepth>0.005</minDepth>
		<maxVel>0</maxVel>
		<kp>1e+13</kp>
		<kd>1.0</kd>
		<maxContacts>10</maxContacts>
	</gazebo>
	<gazebo reference="robotiq_85_left_finger_link">
		<provideFeedback>true</provideFeedback>
		<material>Gazebo/Black</material>
		<implicitSpringDamper>1</implicitSpringDamper>
		<mu1>10</mu1>
		<mu2>100</mu2>
		<minDepth>0.005</minDepth>
		<maxVel>0</maxVel>
		<kp>1e+13</kp>
		<kd>1.0</kd>
		<maxContacts>10</maxContacts>
	</gazebo>
	<gazebo reference="robotiq_85_right_inner_knuckle_link">
		<provideFeedback>true</provideFeedback>
		<material>Gazebo/Black</material>
		<implicitSpringDamper>1</implicitSpringDamper>
		<mu1>10</mu1>
		<mu2>100</mu2>
		<minDepth>0.005</minDepth>
		<maxVel>0</maxVel>
		<kp>1e+13</kp>
		<kd>1.0</kd>
		<maxContacts>10</maxContacts>
	</gazebo>
	<gazebo reference="robotiq_85_right_finger_tip_link">
		<provideFeedback>true</provideFeedback>
		<material>Gazebo/Black</material>
		<implicitSpringDamper>1</implicitSpringDamper>
		<mu1>10</mu1>
		<mu2>100</mu2>
		<minDepth>0.005</minDepth>
		<maxVel>0</maxVel>
		<kp>1e+13</kp>
		<kd>1.0</kd>
		<maxContacts>10</maxContacts>
	</gazebo>
	<gazebo reference="robotiq_85_right_knuckle_link">
		<provideFeedback>true</provideFeedback>
		<material>Gazebo/Black</material>
		<implicitSpringDamper>1</implicitSpringDamper>
		<mu1>10</mu1>
		<mu2>100</mu2>
		<minDepth>0.005</minDepth>
		<maxVel>0</maxVel>
		<kp>1e+13</kp>
		<kd>1.0</kd>
		<maxContacts>10</maxContacts>
	</gazebo>
	<gazebo reference="robotiq_85_right_finger_link">
		<provideFeedback>true</provideFeedback>
		<material>Gazebo/Black</material>
		<implicitSpringDamper>1</implicitSpringDamper>
		<mu1>10</mu1>
		<mu2>100</mu2>
		<minDepth>0.005</minDepth>
		<maxVel>0</maxVel>
		<kp>1e+13</kp>
		<kd>1.0</kd>
		<maxContacts>10</maxContacts>
	</gazebo>
	<link name="tool"/>
	<joint name="tool_joint" type="fixed">
		<parent link="robotiq_85_base_link"/>
		<child link="tool"/>
		<origin rpy="1.57079632679 0 1.57079632679" xyz="0.2445 0 0.0484"/>
	</joint>
	<link name="camera_view_link"/>
	<joint name="camera_view_joint" type="fixed">
		<parent link="robotiq_85_base_link"/>
		<child link="camera_view_link"/>
		<origin rpy="1.57079632679 0 1.57079632679" xyz="0.2445 0 -0.0484"/>
	</joint>
	<gazebo reference="panda_link0">
		<material>Gazebo/White</material>
		<mu1>0.2</mu1>
		<mu2>0.2</mu2>
	</gazebo>
	<gazebo reference="panda_link1">
		<material>Gazebo/White</material>
		<mu1>0.2</mu1>
		<mu2>0.2</mu2>
	</gazebo>
	<gazebo reference="panda_link2">
		<material>Gazebo/White</material>
		<mu1>0.2</mu1>
		<mu2>0.2</mu2>
	</gazebo>
	<gazebo reference="panda_link3">
		<material>Gazebo/White</material>
		<mu1>0.2</mu1>
		<mu2>0.2</mu2>
	</gazebo>
	<gazebo reference="panda_link4">
		<material>Gazebo/White</material>
		<mu1>0.2</mu1>
		<mu2>0.2</mu2>
	</gazebo>
	<gazebo reference="panda_link5">
		<material>Gazebo/White</material>
		<mu1>0.2</mu1>
		<mu2>0.2</mu2>
	</gazebo>
	<gazebo reference="panda_link6">
		<material>Gazebo/White</material>
		<mu1>0.2</mu1>
		<mu2>0.2</mu2>
	</gazebo>
	<gazebo reference="panda_link7">
		<material>Gazebo/White</material>
		<mu1>0.2</mu1>
		<mu2>0.2</mu2>
	</gazebo>
	<gazebo reference="panda_link8">
		<material>Gazebo/White</material>
		<mu1>0.2</mu1>
		<mu2>0.2</mu2>
	</gazebo>
	<transmission name="panda_tran_1">
		<type>transmission_interface/SimpleTransmission</type>
		<joint name="panda_joint1">
			<hardwareInterface>hardware_interface/EffortJointInterface</hardwareInterface>
		</joint>
		<actuator name="panda_motor_1">
			<hardwareInterface>hardware_interface/EffortJointInterface</hardwareInterface>
			<mechanicalReduction>1</mechanicalReduction>
		</actuator>
	</transmission>
	<transmission name="panda_tran_2">
		<type>transmission_interface/SimpleTransmission</type>
		<joint name="panda_joint2">
			<hardwareInterface>hardware_interface/EffortJointInterface</hardwareInterface>
		</joint>
		<actuator name="panda_motor_2">
			<hardwareInterface>hardware_interface/EffortJointInterface</hardwareInterface>
			<mechanicalReduction>1</mechanicalReduction>
		</actuator>
	</transmission>
	<transmission name="panda_tran_3">
		<type>transmission_interface/SimpleTransmission</type>
		<joint name="panda_joint3">
			<hardwareInterface>hardware_interface/EffortJointInterface</hardwareInterface>
		</joint>
		<actuator name="panda_motor_3">
			<hardwareInterface>hardware_interface/EffortJointInterface</hardwareInterface>
			<mechanicalReduction>1</mechanicalReduction>
		</actuator>
	</transmission>
	<transmission name="panda_tran_4">
		<type>transmission_interface/SimpleTransmission</type>
		<joint name="panda_joint4">
			<hardwareInterface>hardware_interface/EffortJointInterface</hardwareInterface>
		</joint>
		<actuator name="panda_motor_4">
			<hardwareInterface>hardware_interface/EffortJointInterface</hardwareInterface>
			<mechanicalReduction>1</mechanicalReduction>
		</actuator>
	</transmission>
	<transmission name="panda_tran_5">
		<type>transmission_interface/SimpleTransmission</type>
		<joint name="panda_joint5">
			<hardwareInterface>hardware_interface/EffortJointInterface</hardwareInterface>
		</joint>
		<actuator name="panda_motor_5">
			<hardwareInterface>hardware_interface/EffortJointInterface</hardwareInterface>
			<mechanicalReduction>1</mechanicalReduction>
		</actuator>
	</transmission>
	<transmission name="panda_tran_6">
		<type>transmission_interface/SimpleTransmission</type>
		<joint name="panda_joint6">
			<hardwareInterface>hardware_interface/EffortJointInterface</hardwareInterface>
		</joint>
		<actuator name="panda_motor_6">
			<hardwareInterface>hardware_interface/EffortJointInterface</hardwareInterface>
			<mechanicalReduction>1</mechanicalReduction>
		</actuator>
	</transmission>
	<transmission name="panda_tran_7">
		<type>transmission_interface/SimpleTransmission</type>
		<joint name="panda_joint7">
			<hardwareInterface>hardware_interface/EffortJointInterface</hardwareInterface>
		</joint>
		<actuator name="panda_motor_7">
			<hardwareInterface>hardware_interface/EffortJointInterface</hardwareInterface>
			<mechanicalReduction>1</mechanicalReduction>
		</actuator>
	</transmission>
	<gazebo>
		<plugin filename="libgazebo_ros_control.so" name="gazebo_ros_control"/>
	</gazebo>
</robot>
